<?xml version="1.0" ?>

<robot name="robot" xmlns:xacro="http://www.ros.org/wiki/xacro">
    <link name="base_link">
        <visual>
            <origin rpy="0 0 0" xyz="0 0 0"/>
            <geometry>
                <box size="1 1 1" />
            </geometry>
        </visual>
    </link>

    <joint name="joint1" type="revolute">
        <axis xyz="0 0 1"/>
        <limit effort="1000.0" lower="-3.14" upper="3.14" velocity="0.5"/>
        <origin rpy="0 0 0" xyz="0 0 0.5"/>
        <parent link="base_link"/>
        <child link="link_01"/>
    </joint>
        
    <link name="link_01">
        <visual>
            <origin rpy="0 0 0" xyz="0 0 0.2"/>
            <geometry>
                <cylinder radius="0.35" length="0.4" />
            </geometry>
        </visual>
    </link>


    <joint name="joint2" type="revolute">
        <axis xyz="0 1 0"/>
        <limit effort="1000.0" lower="-3.14" upper="3.14" velocity="0.5"/>
        <origin rpy="0 0 0" xyz="0 0 0.4"/>
        <parent link="link_01"/>
        <child link="link_02"/>
    </joint>
        
    <link name="link_02">
        <visual>
            <origin rpy="0 0 0" xyz="0 0 0.4"/>
            <geometry>
                <cylinder radius="0.15" length="0.8" />
            </geometry>
        </visual>
    </link>

        <joint name="joint3" type="revolute">
        <axis xyz="0 1 0"/>
        <limit effort="1000.0" lower="-3.14" upper="3.14" velocity="0.5"/>
        <origin rpy="0 0 0" xyz="0 0 0.8"/>
        <parent link="link_02"/>
        <child link="link_03"/>
    </joint>
        
    <link name="link_03">
        <visual>
            <origin rpy="0 0 0" xyz="0 0 0.4"/>
            <geometry>
                <cylinder radius="0.15" length="0.8" />
            </geometry>
        </visual>
    </link>

        <joint name="joint4" type="revolute">
        <axis xyz="0 1 0"/>
        <limit effort="1000.0" lower="-3.14" upper="3.14" velocity="0.5"/>
        <origin rpy="0 0 0" xyz="0 0 0.8"/>
        <parent link="link_03"/>
        <child link="link_04"/>
    </joint>
        
    <link name="link_04">
        <visual>
            <origin rpy="0 0 0" xyz="0 0 0.4"/>
            <geometry>
                <cylinder radius="0.15" length="0.8" />
            </geometry>
        </visual>
    </link>

        <joint name="joint5" type="revolute">
        <axis xyz="0 0 1"/>
        <limit effort="1000.0" lower="-3.14" upper="3.14" velocity="0.5"/>
        <origin rpy="0 0 0" xyz="0 0 0.8"/>
        <parent link="link_04"/>
        <child link="link_05"/>
    </joint>
        
    <link name="link_05">
        <visual>
            <origin rpy="0 0 0" xyz="0 0 0.125"/>
            <geometry>
                <cylinder radius="0.15" length="0.25" />
            </geometry>
        </visual>
    </link>



</robot>